<?xml version="1.0"?>
<robot xmlns:xacro="http://www.ros.org/wiki/xacro">
  <xacro:property name="wheel_width" value="0.01"/>
  <xacro:property name="wheel_radius" value="0.04"/>
  <xacro:property name="wheel_mass" value="0.1"/>

  <xacro:macro name="wheel" params="name parent *origin *visual">
    <joint name="${parent}_to_${name}" type="continuous">
      <parent link="${parent}"/>
      <child link="${name}"/>
      <xacro:insert_block name="origin"/>
      <axis xyz="0 1 0"/>
    </joint>

    <link name="${name}">
      <xacro:insert_block name="visual"/>

      <collision>
        <origin xyz="0 0 0" rpy="${HALF_PI} 0 0"/>
        <geometry>
          <cylinder length="${wheel_width}" radius="${wheel_radius}"/>
        </geometry>
      </collision>

      <xacro:cylinder_inertia m="${wheel_mass}" r="${wheel_radius}" h="${wheel_width}"/>
    </link>

    <gazebo reference="${name}">
      <mu1>100000.0</mu1>
      <mu2>100000.0</mu2>
      <kp>1000000.0</kp>
      <kd>1.0</kd>
    </gazebo>
  </xacro:macro>

  <xacro:macro name="left_wheel" params="name parent *origin">
    <xacro:wheel name="${name}" parent="${parent}">
      <xacro:insert_block name="origin"/>

      <visual>
        <origin xyz="0 0 0" rpy="0 0 -${HALF_PI}"/>
        <geometry>
          <mesh filename="package://clownbot_description/meshes/wheel.dae"/>
        </geometry>
      </visual>
    </xacro:wheel>
  </xacro:macro>

  <xacro:macro name="right_wheel" params="name parent *origin">
    <xacro:wheel name="${name}" parent="${parent}">
      <xacro:insert_block name="origin"/>

      <visual>
        <origin xyz="0 0 0" rpy="0 0 ${HALF_PI}"/>
        <geometry>
          <mesh filename="package://clownbot_description/meshes/wheel.dae"/>
        </geometry>
      </visual>
    </xacro:wheel>
  </xacro:macro>
</robot>
